version: '3.8'

services:
  db:
    image: postgres:latest
    container_name: postgres_db
    environment:
      POSTGRES_USER: ${DB_USER}
      POSTGRES_PASSWORD: ${DB_PASSWORD}
      POSTGRES_DB: ${DB_NAME}
    ports:
      - "5432:5432"
    volumes:
      - pg_data:/var/lib/postgresql/data
    networks:
      - etl_network
    healthcheck:
      test: ["CMD-SHELL", "pg_isready -U ${DB_USER} -d ${DB_NAME}"]
      interval: 5s
      timeout: 5s
      retries: 5

  pgadmin:
    image: dpage/pgadmin4
    container_name: pgadmin
    environment:
      - PGADMIN_DEFAULT_EMAIL=${PGADMIN_DEFAULT_EMAIL}
      - PGADMIN_DEFAULT_PASSWORD=${PGADMIN_DEFAULT_PASSWORD}
    ports:
      - "5050:80"
    volumes:
      - pgadmin_data:/var/lib/pgadmin
    depends_on:
      db:
        condition: service_healthy
    networks:
      - etl_network
      
  etl:
    build:
      context: .
    container_name: etl_container
    depends_on:
      - db
    environment:
      DB_HOST: ${DB_HOST}
      DB_PORT: ${DB_PORT}
      DB_NAME: ${DB_NAME}
      DB_USER: ${DB_USER}
      DB_PASSWORD: ${DB_PASSWORD}
    volumes:
      - .:/app
    command: ["python", "etl.py"]
    networks:
      - etl_network

volumes:
  pg_data:
  pgadmin_data:
networks:
  etl_network:
    driver: bridge
